
  0%|                                                                                                                                                                                                                                                     | 0/23795 [00:00<?, ?it/s]Error in sys.excepthook:
Traceback (most recent call last):
  File "/home/vince/miniconda3/envs/distil/lib/python3.10/linecache.py", line 46, in getlines
    return updatecache(filename, module_globals)
  File "/home/vince/miniconda3/envs/distil/lib/python3.10/linecache.py", line 137, in updatecache
    lines = fp.readlines()
  File "/home/vince/miniconda3/envs/distil/lib/python3.10/codecs.py", line 319, in decode
    def decode(self, input, final=False):
  File "/home/vince/miniconda3/envs/distil/lib/python3.10/site-packages/torch/utils/data/_utils/signal_handling.py", line 66, in handler
    _error_if_any_worker_fails()
RuntimeError: DataLoader worker (pid 20158) exited unexpectedly with exit code 1. Details are lost due to multiprocessing. Rerunning with num_workers=0 may give better error trace.
Original exception was:
Traceback (most recent call last):
  File "/home/vince/miniconda3/envs/distil/lib/python3.10/site-packages/torch/utils/data/dataloader.py", line 630, in __next__
    data = self._next_data()
  File "/home/vince/miniconda3/envs/distil/lib/python3.10/site-packages/torch/utils/data/dataloader.py", line 1328, in _next_data
    idx, data = self._get_data()
  File "/home/vince/miniconda3/envs/distil/lib/python3.10/site-packages/torch/utils/data/dataloader.py", line 1284, in _get_data
    success, data = self._try_get_data()
  File "/home/vince/miniconda3/envs/distil/lib/python3.10/site-packages/torch/utils/data/dataloader.py", line 1132, in _try_get_data
    data = self._data_queue.get(timeout=timeout)
  File "/home/vince/miniconda3/envs/distil/lib/python3.10/queue.py", line 180, in get
    self.not_empty.wait(remaining)
  File "/home/vince/miniconda3/envs/distil/lib/python3.10/threading.py", line 324, in wait
    gotit = waiter.acquire(True, timeout)
KeyboardInterrupt
During handling of the above exception, another exception occurred:
Traceback (most recent call last):
  File "/home/vince/embedding_training/./run_mlm.py", line 817, in <module>
    main()
  File "/home/vince/embedding_training/./run_mlm.py", line 755, in main
    train_result = trainer.train(resume_from_checkpoint=checkpoint)
  File "/home/vince/miniconda3/envs/distil/lib/python3.10/site-packages/transformers/trainer.py", line 1530, in train
    return inner_training_loop(
  File "/home/vince/miniconda3/envs/distil/lib/python3.10/site-packages/transformers/trainer.py", line 1836, in _inner_training_loop
    for step, inputs in enumerate(epoch_iterator):
  File "/home/vince/miniconda3/envs/distil/lib/python3.10/site-packages/accelerate/data_loader.py", line 451, in __iter__
    current_batch = next(dataloader_iter)
  File "/home/vince/miniconda3/envs/distil/lib/python3.10/site-packages/torch/utils/data/dataloader.py", line 626, in __next__
    with torch.autograd.profiler.record_function(self._profile_name):
  File "/home/vince/miniconda3/envs/distil/lib/python3.10/site-packages/torch/autograd/profiler.py", line 648, in __exit__
    torch.ops.profiler._record_function_exit._RecordFunction(record)
  File "/home/vince/miniconda3/envs/distil/lib/python3.10/site-packages/torch/_ops.py", line 641, in __getattr__
    def __getattr__(self, key):
KeyboardInterrupt